<robot name = "robot">
<link name="limb0">
        <inertial>
            <origin xyz="-3.0 0 0.45" rpy="0 0 0"/>
            <mass value="1" />
            <inertia ixx="100" ixy="0" ixz="0" iyy="100" iyz="0" izz="100" />
        </inertial>
        <visual>
            <origin xyz="-3.0 0 0.45" rpy="0 0 0"/>
            <geometry>
                <box size="6 1 0.5" />
            </geometry>
            <material name="green">
                <color rgba="0 1 0 1"/>
            </material>
        </visual>
        <collision>
            <origin xyz="-3.0 0 0.45" rpy="0 0 0"/>
            <geometry>
                <box size="6 1 0.5" />
            </geometry>
        </collision>
    </link>
    <joint name="limb0_limb1" type="revolute">
       <parent link="limb0"/>
       <child  link="limb1"/>
       <origin rpy="0 0 0" xyz="-5.5 -0.5 0.45" />
       <axis xyz="0 1 0"/>
       <limit effort="0.0" lower="-3.14159" upper="3.14159" velocity="0.0"/>
    </joint>
<link name="limb1">
        <inertial>
            <origin xyz="0 -0.25 0" rpy="0 0 0"/>
            <mass value="1" />
            <inertia ixx="100" ixy="0" ixz="0" iyy="100" iyz="0" izz="100" />
        </inertial>
        <visual>
            <origin xyz="0 -0.25 0" rpy="0 0 0"/>
            <geometry>
                <box size="0.2 0.5 0.2" />
            </geometry>
            <material name="blue">
                <color rgba="0 0 1 1"/>
            </material>
        </visual>
        <collision>
            <origin xyz="0 -0.25 0" rpy="0 0 0"/>
            <geometry>
                <box size="0.2 0.5 0.2" />
            </geometry>
        </collision>
    </link>
    <joint name="limb1_limb2" type="revolute">
       <parent link="limb1"/>
       <child  link="limb2"/>
       <origin rpy="0 0 0" xyz="0 -0.5 0" />
       <axis xyz="1 0 0"/>
       <limit effort="0.0" lower="-3.14159" upper="3.14159" velocity="0.0"/>
    </joint>
<link name="limb2">
        <inertial>
            <origin xyz="0 0 -0.2" rpy="0 0 0"/>
            <mass value="1" />
            <inertia ixx="100" ixy="0" ixz="0" iyy="100" iyz="0" izz="100" />
        </inertial>
        <visual>
            <origin xyz="0 0 -0.2" rpy="0 0 0"/>
            <geometry>
                <box size="0.13323885736747101 0.483466825708936 0.6486339551805521" />
            </geometry>
            <material name="green">
                <color rgba="0 1 0 1"/>
            </material>
        </visual>
        <collision>
            <origin xyz="0 0 -0.2" rpy="0 0 0"/>
            <geometry>
                <box size="0.13323885736747101 0.483466825708936 0.6486339551805521" />
            </geometry>
        </collision>
    </link>
    <joint name="limb0_limb3" type="revolute">
       <parent link="limb0"/>
       <child  link="limb3"/>
       <origin rpy="0 0 0" xyz="-4.5 -0.5 0.45" />
       <axis xyz="0 1 0"/>
       <limit effort="0.0" lower="-3.14159" upper="3.14159" velocity="0.0"/>
    </joint>
<link name="limb3">
        <inertial>
            <origin xyz="0 -0.25 0" rpy="0 0 0"/>
            <mass value="1" />
            <inertia ixx="100" ixy="0" ixz="0" iyy="100" iyz="0" izz="100" />
        </inertial>
        <visual>
            <origin xyz="0 -0.25 0" rpy="0 0 0"/>
            <geometry>
                <box size="0.2 0.5 0.2" />
            </geometry>
            <material name="blue">
                <color rgba="0 0 1 1"/>
            </material>
        </visual>
        <collision>
            <origin xyz="0 -0.25 0" rpy="0 0 0"/>
            <geometry>
                <box size="0.2 0.5 0.2" />
            </geometry>
        </collision>
    </link>
    <joint name="limb3_limb4" type="revolute">
       <parent link="limb3"/>
       <child  link="limb4"/>
       <origin rpy="0 0 0" xyz="0 -0.5 0" />
       <axis xyz="1 0 0"/>
       <limit effort="0.0" lower="-3.14159" upper="3.14159" velocity="0.0"/>
    </joint>
<link name="limb4">
        <inertial>
            <origin xyz="0 0 -0.2" rpy="0 0 0"/>
            <mass value="1" />
            <inertia ixx="100" ixy="0" ixz="0" iyy="100" iyz="0" izz="100" />
        </inertial>
        <visual>
            <origin xyz="0 0 -0.2" rpy="0 0 0"/>
            <geometry>
                <box size="0.23540828463586774 0.37711922606718223 0.5527653916435739" />
            </geometry>
            <material name="green">
                <color rgba="0 1 0 1"/>
            </material>
        </visual>
        <collision>
            <origin xyz="0 0 -0.2" rpy="0 0 0"/>
            <geometry>
                <box size="0.23540828463586774 0.37711922606718223 0.5527653916435739" />
            </geometry>
        </collision>
    </link>
    <joint name="limb0_limb5" type="revolute">
       <parent link="limb0"/>
       <child  link="limb5"/>
       <origin rpy="0 0 0" xyz="-3.5 -0.5 0.45" />
       <axis xyz="0 1 0"/>
       <limit effort="0.0" lower="-3.14159" upper="3.14159" velocity="0.0"/>
    </joint>
<link name="limb5">
        <inertial>
            <origin xyz="0 -0.25 0" rpy="0 0 0"/>
            <mass value="1" />
            <inertia ixx="100" ixy="0" ixz="0" iyy="100" iyz="0" izz="100" />
        </inertial>
        <visual>
            <origin xyz="0 -0.25 0" rpy="0 0 0"/>
            <geometry>
                <box size="0.2 0.5 0.2" />
            </geometry>
            <material name="blue">
                <color rgba="0 0 1 1"/>
            </material>
        </visual>
        <collision>
            <origin xyz="0 -0.25 0" rpy="0 0 0"/>
            <geometry>
                <box size="0.2 0.5 0.2" />
            </geometry>
        </collision>
    </link>
    <joint name="limb5_limb6" type="revolute">
       <parent link="limb5"/>
       <child  link="limb6"/>
       <origin rpy="0 0 0" xyz="0 -0.5 0" />
       <axis xyz="1 0 0"/>
       <limit effort="0.0" lower="-3.14159" upper="3.14159" velocity="0.0"/>
    </joint>
<link name="limb6">
        <inertial>
            <origin xyz="0 0 -0.2" rpy="0 0 0"/>
            <mass value="1" />
            <inertia ixx="100" ixy="0" ixz="0" iyy="100" iyz="0" izz="100" />
        </inertial>
        <visual>
            <origin xyz="0 0 -0.2" rpy="0 0 0"/>
            <geometry>
                <box size="0.1736985145751206 0.3317656270496058 0.23801987773730146" />
            </geometry>
            <material name="green">
                <color rgba="0 1 0 1"/>
            </material>
        </visual>
        <collision>
            <origin xyz="0 0 -0.2" rpy="0 0 0"/>
            <geometry>
                <box size="0.1736985145751206 0.3317656270496058 0.23801987773730146" />
            </geometry>
        </collision>
    </link>
    <joint name="limb0_limb7" type="revolute">
       <parent link="limb0"/>
       <child  link="limb7"/>
       <origin rpy="0 0 0" xyz="-2.5 -0.5 0.45" />
       <axis xyz="0 1 0"/>
       <limit effort="0.0" lower="-3.14159" upper="3.14159" velocity="0.0"/>
    </joint>
<link name="limb7">
        <inertial>
            <origin xyz="0 -0.25 0" rpy="0 0 0"/>
            <mass value="1" />
            <inertia ixx="100" ixy="0" ixz="0" iyy="100" iyz="0" izz="100" />
        </inertial>
        <visual>
            <origin xyz="0 -0.25 0" rpy="0 0 0"/>
            <geometry>
                <box size="0.2 0.5 0.2" />
            </geometry>
            <material name="blue">
                <color rgba="0 0 1 1"/>
            </material>
        </visual>
        <collision>
            <origin xyz="0 -0.25 0" rpy="0 0 0"/>
            <geometry>
                <box size="0.2 0.5 0.2" />
            </geometry>
        </collision>
    </link>
    <joint name="limb7_limb8" type="revolute">
       <parent link="limb7"/>
       <child  link="limb8"/>
       <origin rpy="0 0 0" xyz="0 -0.5 0" />
       <axis xyz="1 0 0"/>
       <limit effort="0.0" lower="-3.14159" upper="3.14159" velocity="0.0"/>
    </joint>
<link name="limb8">
        <inertial>
            <origin xyz="0 0 -0.2" rpy="0 0 0"/>
            <mass value="1" />
            <inertia ixx="100" ixy="0" ixz="0" iyy="100" iyz="0" izz="100" />
        </inertial>
        <visual>
            <origin xyz="0 0 -0.2" rpy="0 0 0"/>
            <geometry>
                <box size="0.211911771017272 0.39631404509585455 0.4196470906662977" />
            </geometry>
            <material name="green">
                <color rgba="0 1 0 1"/>
            </material>
        </visual>
        <collision>
            <origin xyz="0 0 -0.2" rpy="0 0 0"/>
            <geometry>
                <box size="0.211911771017272 0.39631404509585455 0.4196470906662977" />
            </geometry>
        </collision>
    </link>
    <joint name="limb0_limb9" type="revolute">
       <parent link="limb0"/>
       <child  link="limb9"/>
       <origin rpy="0 0 0" xyz="-1.5 -0.5 0.45" />
       <axis xyz="0 1 0"/>
       <limit effort="0.0" lower="-3.14159" upper="3.14159" velocity="0.0"/>
    </joint>
<link name="limb9">
        <inertial>
            <origin xyz="0 -0.25 0" rpy="0 0 0"/>
            <mass value="1" />
            <inertia ixx="100" ixy="0" ixz="0" iyy="100" iyz="0" izz="100" />
        </inertial>
        <visual>
            <origin xyz="0 -0.25 0" rpy="0 0 0"/>
            <geometry>
                <box size="0.2 0.5 0.2" />
            </geometry>
            <material name="blue">
                <color rgba="0 0 1 1"/>
            </material>
        </visual>
        <collision>
            <origin xyz="0 -0.25 0" rpy="0 0 0"/>
            <geometry>
                <box size="0.2 0.5 0.2" />
            </geometry>
        </collision>
    </link>
    <joint name="limb9_limb10" type="revolute">
       <parent link="limb9"/>
       <child  link="limb10"/>
       <origin rpy="0 0 0" xyz="0 -0.5 0" />
       <axis xyz="1 0 0"/>
       <limit effort="0.0" lower="-3.14159" upper="3.14159" velocity="0.0"/>
    </joint>
<link name="limb10">
        <inertial>
            <origin xyz="0 0 -0.2" rpy="0 0 0"/>
            <mass value="1" />
            <inertia ixx="100" ixy="0" ixz="0" iyy="100" iyz="0" izz="100" />
        </inertial>
        <visual>
            <origin xyz="0 0 -0.2" rpy="0 0 0"/>
            <geometry>
                <box size="0.11398672301070159 0.4318573652522619 0.58920650858361" />
            </geometry>
            <material name="green">
                <color rgba="0 1 0 1"/>
            </material>
        </visual>
        <collision>
            <origin xyz="0 0 -0.2" rpy="0 0 0"/>
            <geometry>
                <box size="0.11398672301070159 0.4318573652522619 0.58920650858361" />
            </geometry>
        </collision>
    </link>
    <joint name="limb0_limb11" type="revolute">
       <parent link="limb0"/>
       <child  link="limb11"/>
       <origin rpy="0 0 0" xyz="-0.5 -0.5 0.45" />
       <axis xyz="0 1 0"/>
       <limit effort="0.0" lower="-3.14159" upper="3.14159" velocity="0.0"/>
    </joint>
<link name="limb11">
        <inertial>
            <origin xyz="0 -0.25 0" rpy="0 0 0"/>
            <mass value="1" />
            <inertia ixx="100" ixy="0" ixz="0" iyy="100" iyz="0" izz="100" />
        </inertial>
        <visual>
            <origin xyz="0 -0.25 0" rpy="0 0 0"/>
            <geometry>
                <box size="0.2 0.5 0.2" />
            </geometry>
            <material name="blue">
                <color rgba="0 0 1 1"/>
            </material>
        </visual>
        <collision>
            <origin xyz="0 -0.25 0" rpy="0 0 0"/>
            <geometry>
                <box size="0.2 0.5 0.2" />
            </geometry>
        </collision>
    </link>
    <joint name="limb11_limb12" type="revolute">
       <parent link="limb11"/>
       <child  link="limb12"/>
       <origin rpy="0 0 0" xyz="0 -0.5 0" />
       <axis xyz="1 0 0"/>
       <limit effort="0.0" lower="-3.14159" upper="3.14159" velocity="0.0"/>
    </joint>
<link name="limb12">
        <inertial>
            <origin xyz="0 0 -0.2" rpy="0 0 0"/>
            <mass value="1" />
            <inertia ixx="100" ixy="0" ixz="0" iyy="100" iyz="0" izz="100" />
        </inertial>
        <visual>
            <origin xyz="0 0 -0.2" rpy="0 0 0"/>
            <geometry>
                <box size="0.15281873226544979 0.4978920951212295 0.4433438627287204" />
            </geometry>
            <material name="green">
                <color rgba="0 1 0 1"/>
            </material>
        </visual>
        <collision>
            <origin xyz="0 0 -0.2" rpy="0 0 0"/>
            <geometry>
                <box size="0.15281873226544979 0.4978920951212295 0.4433438627287204" />
            </geometry>
        </collision>
    </link>
    <joint name="limb0_limb13" type="revolute">
       <parent link="limb0"/>
       <child  link="limb13"/>
       <origin rpy="0 0 0" xyz="-5.5 0.5 0.45" />
       <axis xyz="0 1 0"/>
       <limit effort="0.0" lower="-3.14159" upper="3.14159" velocity="0.0"/>
    </joint>
<link name="limb13">
        <inertial>
            <origin xyz="0 0.25 0" rpy="0 0 0"/>
            <mass value="1" />
            <inertia ixx="100" ixy="0" ixz="0" iyy="100" iyz="0" izz="100" />
        </inertial>
        <visual>
            <origin xyz="0 0.25 0" rpy="0 0 0"/>
            <geometry>
                <box size="0.2 0.5 0.2" />
            </geometry>
            <material name="blue">
                <color rgba="0 0 1 1"/>
            </material>
        </visual>
        <collision>
            <origin xyz="0 0.25 0" rpy="0 0 0"/>
            <geometry>
                <box size="0.2 0.5 0.2" />
            </geometry>
        </collision>
    </link>
    <joint name="limb13_limb14" type="revolute">
       <parent link="limb13"/>
       <child  link="limb14"/>
       <origin rpy="0 0 0" xyz="0 0.5 0" />
       <axis xyz="1 0 0"/>
       <limit effort="0.0" lower="-3.14159" upper="3.14159" velocity="0.0"/>
    </joint>
<link name="limb14">
        <inertial>
            <origin xyz="0 0 -0.2" rpy="0 0 0"/>
            <mass value="1" />
            <inertia ixx="100" ixy="0" ixz="0" iyy="100" iyz="0" izz="100" />
        </inertial>
        <visual>
            <origin xyz="0 0 -0.2" rpy="0 0 0"/>
            <geometry>
                <box size="0.1702200221621705 0.43671559061120224 0.347847773172721" />
            </geometry>
            <material name="blue">
                <color rgba="0 0 1 1"/>
            </material>
        </visual>
        <collision>
            <origin xyz="0 0 -0.2" rpy="0 0 0"/>
            <geometry>
                <box size="0.1702200221621705 0.43671559061120224 0.347847773172721" />
            </geometry>
        </collision>
    </link>
    <joint name="limb0_limb15" type="revolute">
       <parent link="limb0"/>
       <child  link="limb15"/>
       <origin rpy="0 0 0" xyz="-4.5 0.5 0.45" />
       <axis xyz="0 1 0"/>
       <limit effort="0.0" lower="-3.14159" upper="3.14159" velocity="0.0"/>
    </joint>
<link name="limb15">
        <inertial>
            <origin xyz="0 0.25 0" rpy="0 0 0"/>
            <mass value="1" />
            <inertia ixx="100" ixy="0" ixz="0" iyy="100" iyz="0" izz="100" />
        </inertial>
        <visual>
            <origin xyz="0 0.25 0" rpy="0 0 0"/>
            <geometry>
                <box size="0.2 0.5 0.2" />
            </geometry>
            <material name="blue">
                <color rgba="0 0 1 1"/>
            </material>
        </visual>
        <collision>
            <origin xyz="0 0.25 0" rpy="0 0 0"/>
            <geometry>
                <box size="0.2 0.5 0.2" />
            </geometry>
        </collision>
    </link>
    <joint name="limb15_limb16" type="revolute">
       <parent link="limb15"/>
       <child  link="limb16"/>
       <origin rpy="0 0 0" xyz="0 0.5 0" />
       <axis xyz="1 0 0"/>
       <limit effort="0.0" lower="-3.14159" upper="3.14159" velocity="0.0"/>
    </joint>
<link name="limb16">
        <inertial>
            <origin xyz="0 0 -0.2" rpy="0 0 0"/>
            <mass value="1" />
            <inertia ixx="100" ixy="0" ixz="0" iyy="100" iyz="0" izz="100" />
        </inertial>
        <visual>
            <origin xyz="0 0 -0.2" rpy="0 0 0"/>
            <geometry>
                <box size="0.23232385749626303 0.4744083430838929 0.1625755470612773" />
            </geometry>
            <material name="blue">
                <color rgba="0 0 1 1"/>
            </material>
        </visual>
        <collision>
            <origin xyz="0 0 -0.2" rpy="0 0 0"/>
            <geometry>
                <box size="0.23232385749626303 0.4744083430838929 0.1625755470612773" />
            </geometry>
        </collision>
    </link>
    <joint name="limb0_limb17" type="revolute">
       <parent link="limb0"/>
       <child  link="limb17"/>
       <origin rpy="0 0 0" xyz="-3.5 0.5 0.45" />
       <axis xyz="0 1 0"/>
       <limit effort="0.0" lower="-3.14159" upper="3.14159" velocity="0.0"/>
    </joint>
<link name="limb17">
        <inertial>
            <origin xyz="0 0.25 0" rpy="0 0 0"/>
            <mass value="1" />
            <inertia ixx="100" ixy="0" ixz="0" iyy="100" iyz="0" izz="100" />
        </inertial>
        <visual>
            <origin xyz="0 0.25 0" rpy="0 0 0"/>
            <geometry>
                <box size="0.2 0.5 0.2" />
            </geometry>
            <material name="blue">
                <color rgba="0 0 1 1"/>
            </material>
        </visual>
        <collision>
            <origin xyz="0 0.25 0" rpy="0 0 0"/>
            <geometry>
                <box size="0.2 0.5 0.2" />
            </geometry>
        </collision>
    </link>
    <joint name="limb17_limb18" type="revolute">
       <parent link="limb17"/>
       <child  link="limb18"/>
       <origin rpy="0 0 0" xyz="0 0.5 0" />
       <axis xyz="1 0 0"/>
       <limit effort="0.0" lower="-3.14159" upper="3.14159" velocity="0.0"/>
    </joint>
<link name="limb18">
        <inertial>
            <origin xyz="0 0 -0.2" rpy="0 0 0"/>
            <mass value="1" />
            <inertia ixx="100" ixy="0" ixz="0" iyy="100" iyz="0" izz="100" />
        </inertial>
        <visual>
            <origin xyz="0 0 -0.2" rpy="0 0 0"/>
            <geometry>
                <box size="0.16330578027834877 0.34908190441727044 0.19777351932726392" />
            </geometry>
            <material name="blue">
                <color rgba="0 0 1 1"/>
            </material>
        </visual>
        <collision>
            <origin xyz="0 0 -0.2" rpy="0 0 0"/>
            <geometry>
                <box size="0.16330578027834877 0.34908190441727044 0.19777351932726392" />
            </geometry>
        </collision>
    </link>
    <joint name="limb0_limb19" type="revolute">
       <parent link="limb0"/>
       <child  link="limb19"/>
       <origin rpy="0 0 0" xyz="-2.5 0.5 0.45" />
       <axis xyz="0 1 0"/>
       <limit effort="0.0" lower="-3.14159" upper="3.14159" velocity="0.0"/>
    </joint>
<link name="limb19">
        <inertial>
            <origin xyz="0 0.25 0" rpy="0 0 0"/>
            <mass value="1" />
            <inertia ixx="100" ixy="0" ixz="0" iyy="100" iyz="0" izz="100" />
        </inertial>
        <visual>
            <origin xyz="0 0.25 0" rpy="0 0 0"/>
            <geometry>
                <box size="0.2 0.5 0.2" />
            </geometry>
            <material name="blue">
                <color rgba="0 0 1 1"/>
            </material>
        </visual>
        <collision>
            <origin xyz="0 0.25 0" rpy="0 0 0"/>
            <geometry>
                <box size="0.2 0.5 0.2" />
            </geometry>
        </collision>
    </link>
    <joint name="limb19_limb20" type="revolute">
       <parent link="limb19"/>
       <child  link="limb20"/>
       <origin rpy="0 0 0" xyz="0 0.5 0" />
       <axis xyz="1 0 0"/>
       <limit effort="0.0" lower="-3.14159" upper="3.14159" velocity="0.0"/>
    </joint>
<link name="limb20">
        <inertial>
            <origin xyz="0 0 -0.2" rpy="0 0 0"/>
            <mass value="1" />
            <inertia ixx="100" ixy="0" ixz="0" iyy="100" iyz="0" izz="100" />
        </inertial>
        <visual>
            <origin xyz="0 0 -0.2" rpy="0 0 0"/>
            <geometry>
                <box size="0.13998439769590354 0.32872669001325494 0.7189710482094831" />
            </geometry>
            <material name="green">
                <color rgba="0 1 0 1"/>
            </material>
        </visual>
        <collision>
            <origin xyz="0 0 -0.2" rpy="0 0 0"/>
            <geometry>
                <box size="0.13998439769590354 0.32872669001325494 0.7189710482094831" />
            </geometry>
        </collision>
    </link>
    <joint name="limb0_limb21" type="revolute">
       <parent link="limb0"/>
       <child  link="limb21"/>
       <origin rpy="0 0 0" xyz="-1.5 0.5 0.45" />
       <axis xyz="0 1 0"/>
       <limit effort="0.0" lower="-3.14159" upper="3.14159" velocity="0.0"/>
    </joint>
<link name="limb21">
        <inertial>
            <origin xyz="0 0.25 0" rpy="0 0 0"/>
            <mass value="1" />
            <inertia ixx="100" ixy="0" ixz="0" iyy="100" iyz="0" izz="100" />
        </inertial>
        <visual>
            <origin xyz="0 0.25 0" rpy="0 0 0"/>
            <geometry>
                <box size="0.2 0.5 0.2" />
            </geometry>
            <material name="blue">
                <color rgba="0 0 1 1"/>
            </material>
        </visual>
        <collision>
            <origin xyz="0 0.25 0" rpy="0 0 0"/>
            <geometry>
                <box size="0.2 0.5 0.2" />
            </geometry>
        </collision>
    </link>
    <joint name="limb21_limb22" type="revolute">
       <parent link="limb21"/>
       <child  link="limb22"/>
       <origin rpy="0 0 0" xyz="0 0.5 0" />
       <axis xyz="1 0 0"/>
       <limit effort="0.0" lower="-3.14159" upper="3.14159" velocity="0.0"/>
    </joint>
<link name="limb22">
        <inertial>
            <origin xyz="0 0 -0.2" rpy="0 0 0"/>
            <mass value="1" />
            <inertia ixx="100" ixy="0" ixz="0" iyy="100" iyz="0" izz="100" />
        </inertial>
        <visual>
            <origin xyz="0 0 -0.2" rpy="0 0 0"/>
            <geometry>
                <box size="0.24496856575433784 0.43949862739077444 0.37306862438049104" />
            </geometry>
            <material name="green">
                <color rgba="0 1 0 1"/>
            </material>
        </visual>
        <collision>
            <origin xyz="0 0 -0.2" rpy="0 0 0"/>
            <geometry>
                <box size="0.24496856575433784 0.43949862739077444 0.37306862438049104" />
            </geometry>
        </collision>
    </link>
    <joint name="limb0_limb23" type="revolute">
       <parent link="limb0"/>
       <child  link="limb23"/>
       <origin rpy="0 0 0" xyz="-0.5 0.5 0.45" />
       <axis xyz="0 1 0"/>
       <limit effort="0.0" lower="-3.14159" upper="3.14159" velocity="0.0"/>
    </joint>
<link name="limb23">
        <inertial>
            <origin xyz="0 0.25 0" rpy="0 0 0"/>
            <mass value="1" />
            <inertia ixx="100" ixy="0" ixz="0" iyy="100" iyz="0" izz="100" />
        </inertial>
        <visual>
            <origin xyz="0 0.25 0" rpy="0 0 0"/>
            <geometry>
                <box size="0.2 0.5 0.2" />
            </geometry>
            <material name="blue">
                <color rgba="0 0 1 1"/>
            </material>
        </visual>
        <collision>
            <origin xyz="0 0.25 0" rpy="0 0 0"/>
            <geometry>
                <box size="0.2 0.5 0.2" />
            </geometry>
        </collision>
    </link>
    <joint name="limb23_limb24" type="revolute">
       <parent link="limb23"/>
       <child  link="limb24"/>
       <origin rpy="0 0 0" xyz="0 0.5 0" />
       <axis xyz="1 0 0"/>
       <limit effort="0.0" lower="-3.14159" upper="3.14159" velocity="0.0"/>
    </joint>
<link name="limb24">
        <inertial>
            <origin xyz="0 0 -0.2" rpy="0 0 0"/>
            <mass value="1" />
            <inertia ixx="100" ixy="0" ixz="0" iyy="100" iyz="0" izz="100" />
        </inertial>
        <visual>
            <origin xyz="0 0 -0.2" rpy="0 0 0"/>
            <geometry>
                <box size="0.2145098166777923 0.4634492364504299 0.4727860809713559" />
            </geometry>
            <material name="blue">
                <color rgba="0 0 1 1"/>
            </material>
        </visual>
        <collision>
            <origin xyz="0 0 -0.2" rpy="0 0 0"/>
            <geometry>
                <box size="0.2145098166777923 0.4634492364504299 0.4727860809713559" />
            </geometry>
        </collision>
    </link>
    <joint name="limb0_limb25" type="revolute">
       <parent link="limb0"/>
       <child  link="limb25"/>
       <origin rpy="0 0 0" xyz="-5.5 0 0.35" />
       <axis xyz="0 0 1"/>
       <limit effort="0.0" lower="-3.14159" upper="3.14159" velocity="0.0"/>
    </joint>
<link name="limb25">
        <inertial>
            <origin xyz="1.2260488410336818 0 0.45" rpy="0 0 0"/>
            <mass value="1" />
            <inertia ixx="100" ixy="0" ixz="0" iyy="100" iyz="0" izz="100" />
        </inertial>
        <visual>
            <origin xyz="1.2260488410336818 0 0.45" rpy="0 0 0"/>
            <geometry>
                <box size="0.26216037943528536 0.4228870777327535 0.5851006032251239" />
            </geometry>
            <material name="blue">
                <color rgba="0 0 1 1"/>
            </material>
        </visual>
        <collision>
            <origin xyz="1.2260488410336818 0 0.45" rpy="0 0 0"/>
            <geometry>
                <box size="0.26216037943528536 0.4228870777327535 0.5851006032251239" />
            </geometry>
        </collision>
    </link>
</robot>