<robot name = "robot">
<link name="limb0">
        <inertial>
            <origin xyz="-2.0 0 0.45" rpy="0 0 0"/>
            <mass value="1" />
            <inertia ixx="100" ixy="0" ixz="0" iyy="100" iyz="0" izz="100" />
        </inertial>
        <visual>
            <origin xyz="-2.0 0 0.45" rpy="0 0 0"/>
            <geometry>
                <box size="4 1 0.5" />
            </geometry>
            <material name="green">
                <color rgba="0 1 0 1"/>
            </material>
        </visual>
        <collision>
            <origin xyz="-2.0 0 0.45" rpy="0 0 0"/>
            <geometry>
                <box size="4 1 0.5" />
            </geometry>
        </collision>
    </link>
    <joint name="limb0_limb1" type="revolute">
       <parent link="limb0"/>
       <child  link="limb1"/>
       <origin rpy="0 0 0" xyz="-3.5 0.5 0.45" />
       <axis xyz="0 1 0"/>
       <limit effort="0.0" lower="-3.14159" upper="3.14159" velocity="0.0"/>
    </joint>
<link name="limb1">
        <inertial>
            <origin xyz="0 0.25 0" rpy="0 0 0"/>
            <mass value="1" />
            <inertia ixx="100" ixy="0" ixz="0" iyy="100" iyz="0" izz="100" />
        </inertial>
        <visual>
            <origin xyz="0 0.25 0" rpy="0 0 0"/>
            <geometry>
                <box size="0.2 0.7 0.2" />
            </geometry>
            <material name="blue">
                <color rgba="0 0 1 1"/>
            </material>
        </visual>
        <collision>
            <origin xyz="0 0.25 0" rpy="0 0 0"/>
            <geometry>
                <box size="0.2 0.7 0.2" />
            </geometry>
        </collision>
    </link>
    <joint name="limb1_limb2" type="revolute">
       <parent link="limb1"/>
       <child  link="limb2"/>
       <origin rpy="0 0 0" xyz="0 0.5 0" />
       <axis xyz="1 0 0"/>
       <limit effort="0.0" lower="-3.14159" upper="3.14159" velocity="0.0"/>
    </joint>
<link name="limb2">
        <inertial>
            <origin xyz="0 0 -0.2" rpy="0 0 0"/>
            <mass value="1" />
            <inertia ixx="100" ixy="0" ixz="0" iyy="100" iyz="0" izz="100" />
        </inertial>
        <visual>
            <origin xyz="0 0 -0.2" rpy="0 0 0"/>
            <geometry>
                <box size="0.2 0.2 0.7" />
            </geometry>
            <material name="blue">
                <color rgba="0 0 1 1"/>
            </material>
        </visual>
        <collision>
            <origin xyz="0 0 -0.2" rpy="0 0 0"/>
            <geometry>
                <box size="0.2 0.2 0.7" />
            </geometry>
        </collision>
    </link>
    <joint name="limb0_limb3" type="revolute">
       <parent link="limb0"/>
       <child  link="limb3"/>
       <origin rpy="0 0 0" xyz="-3.0 0.5 0.45" />
       <axis xyz="0 1 0"/>
       <limit effort="0.0" lower="-3.14159" upper="3.14159" velocity="0.0"/>
    </joint>
<link name="limb3">
        <inertial>
            <origin xyz="0 0.25 0" rpy="0 0 0"/>
            <mass value="1" />
            <inertia ixx="100" ixy="0" ixz="0" iyy="100" iyz="0" izz="100" />
        </inertial>
        <visual>
            <origin xyz="0 0.25 0" rpy="0 0 0"/>
            <geometry>
                <box size="0.2 0.7 0.2" />
            </geometry>
            <material name="blue">
                <color rgba="0 0 1 1"/>
            </material>
        </visual>
        <collision>
            <origin xyz="0 0.25 0" rpy="0 0 0"/>
            <geometry>
                <box size="0.2 0.7 0.2" />
            </geometry>
        </collision>
    </link>
    <joint name="limb3_limb4" type="revolute">
       <parent link="limb3"/>
       <child  link="limb4"/>
       <origin rpy="0 0 0" xyz="0 0.5 0" />
       <axis xyz="1 0 0"/>
       <limit effort="0.0" lower="-3.14159" upper="3.14159" velocity="0.0"/>
    </joint>
<link name="limb4">
        <inertial>
            <origin xyz="0 0 -0.2" rpy="0 0 0"/>
            <mass value="1" />
            <inertia ixx="100" ixy="0" ixz="0" iyy="100" iyz="0" izz="100" />
        </inertial>
        <visual>
            <origin xyz="0 0 -0.2" rpy="0 0 0"/>
            <geometry>
                <box size="0.2 0.2 0.7" />
            </geometry>
            <material name="green">
                <color rgba="0 1 0 1"/>
            </material>
        </visual>
        <collision>
            <origin xyz="0 0 -0.2" rpy="0 0 0"/>
            <geometry>
                <box size="0.2 0.2 0.7" />
            </geometry>
        </collision>
    </link>
    <joint name="limb0_limb5" type="revolute">
       <parent link="limb0"/>
       <child  link="limb5"/>
       <origin rpy="0 0 0" xyz="-2.5 0.5 0.45" />
       <axis xyz="0 1 0"/>
       <limit effort="0.0" lower="-3.14159" upper="3.14159" velocity="0.0"/>
    </joint>
<link name="limb5">
        <inertial>
            <origin xyz="0 0.25 0" rpy="0 0 0"/>
            <mass value="1" />
            <inertia ixx="100" ixy="0" ixz="0" iyy="100" iyz="0" izz="100" />
        </inertial>
        <visual>
            <origin xyz="0 0.25 0" rpy="0 0 0"/>
            <geometry>
                <box size="0.2 0.7 0.2" />
            </geometry>
            <material name="blue">
                <color rgba="0 0 1 1"/>
            </material>
        </visual>
        <collision>
            <origin xyz="0 0.25 0" rpy="0 0 0"/>
            <geometry>
                <box size="0.2 0.7 0.2" />
            </geometry>
        </collision>
    </link>
    <joint name="limb5_limb6" type="revolute">
       <parent link="limb5"/>
       <child  link="limb6"/>
       <origin rpy="0 0 0" xyz="0 0.5 0" />
       <axis xyz="1 0 0"/>
       <limit effort="0.0" lower="-3.14159" upper="3.14159" velocity="0.0"/>
    </joint>
<link name="limb6">
        <inertial>
            <origin xyz="0 0 -0.2" rpy="0 0 0"/>
            <mass value="1" />
            <inertia ixx="100" ixy="0" ixz="0" iyy="100" iyz="0" izz="100" />
        </inertial>
        <visual>
            <origin xyz="0 0 -0.2" rpy="0 0 0"/>
            <geometry>
                <box size="0.2 0.2 0.7" />
            </geometry>
            <material name="blue">
                <color rgba="0 0 1 1"/>
            </material>
        </visual>
        <collision>
            <origin xyz="0 0 -0.2" rpy="0 0 0"/>
            <geometry>
                <box size="0.2 0.2 0.7" />
            </geometry>
        </collision>
    </link>
    <joint name="limb0_limb7" type="revolute">
       <parent link="limb0"/>
       <child  link="limb7"/>
       <origin rpy="0 0 0" xyz="-2.0 0.5 0.45" />
       <axis xyz="0 1 0"/>
       <limit effort="0.0" lower="-3.14159" upper="3.14159" velocity="0.0"/>
    </joint>
<link name="limb7">
        <inertial>
            <origin xyz="0 0.25 0" rpy="0 0 0"/>
            <mass value="1" />
            <inertia ixx="100" ixy="0" ixz="0" iyy="100" iyz="0" izz="100" />
        </inertial>
        <visual>
            <origin xyz="0 0.25 0" rpy="0 0 0"/>
            <geometry>
                <box size="0.2 0.7 0.2" />
            </geometry>
            <material name="blue">
                <color rgba="0 0 1 1"/>
            </material>
        </visual>
        <collision>
            <origin xyz="0 0.25 0" rpy="0 0 0"/>
            <geometry>
                <box size="0.2 0.7 0.2" />
            </geometry>
        </collision>
    </link>
    <joint name="limb7_limb8" type="revolute">
       <parent link="limb7"/>
       <child  link="limb8"/>
       <origin rpy="0 0 0" xyz="0 0.5 0" />
       <axis xyz="1 0 0"/>
       <limit effort="0.0" lower="-3.14159" upper="3.14159" velocity="0.0"/>
    </joint>
<link name="limb8">
        <inertial>
            <origin xyz="0 0 -0.2" rpy="0 0 0"/>
            <mass value="1" />
            <inertia ixx="100" ixy="0" ixz="0" iyy="100" iyz="0" izz="100" />
        </inertial>
        <visual>
            <origin xyz="0 0 -0.2" rpy="0 0 0"/>
            <geometry>
                <box size="0.2 0.2 0.7" />
            </geometry>
            <material name="blue">
                <color rgba="0 0 1 1"/>
            </material>
        </visual>
        <collision>
            <origin xyz="0 0 -0.2" rpy="0 0 0"/>
            <geometry>
                <box size="0.2 0.2 0.7" />
            </geometry>
        </collision>
    </link>
    <joint name="limb0_limb9" type="revolute">
       <parent link="limb0"/>
       <child  link="limb9"/>
       <origin rpy="0 0 0" xyz="-3.5 0 0.35" />
       <axis xyz="0 0 1"/>
       <limit effort="0.0" lower="-3.14159" upper="3.14159" velocity="0.0"/>
    </joint>
<link name="limb9">
        <inertial>
            <origin xyz="-4 0 0.45" rpy="0 0 0"/>
            <mass value="1" />
            <inertia ixx="100" ixy="0" ixz="0" iyy="100" iyz="0" izz="100" />
        </inertial>
        <visual>
            <origin xyz="-4 0 0.45" rpy="0 0 0"/>
            <geometry>
                <box size="0.35026630581219564 0.6916947202418163 0.9872561951159837" />
            </geometry>
            <material name="blue">
                <color rgba="0 0 1 1"/>
            </material>
        </visual>
        <collision>
            <origin xyz="-4 0 0.45" rpy="0 0 0"/>
            <geometry>
                <box size="0.35026630581219564 0.6916947202418163 0.9872561951159837" />
            </geometry>
        </collision>
    </link>
</robot>