<robot name = "robot">
<link name="Torso">
        <inertial>
            <origin xyz="0 0 0.6129705770482038" rpy="0 0 0"/>
            <mass value="1" />
            <inertia ixx="100" ixy="0" ixz="0" iyy="100" iyz="0" izz="100" />
        </inertial>
        <visual>
            <origin xyz="0 0 0.6129705770482038" rpy="0 0 0"/>
            <geometry>
                <box size="2.6952214071644818 2.8030933373978035 1.2259411540964076" />
            </geometry>
            <material name="Green">
                <color rgba="0 180.0 0.0 1.0"/>
            </material>
        </visual>
        <collision>
            <origin xyz="0 0 0.6129705770482038" rpy="0 0 0"/>
            <geometry>
                <box size="2.6952214071644818 2.8030933373978035 1.2259411540964076" />
            </geometry>
        </collision>
    </link>
<link name="Torso1">
        <inertial>
            <origin xyz="0 0.8383363595142133 0" rpy="0 0 0"/>
            <mass value="1" />
            <inertia ixx="100" ixy="0" ixz="0" iyy="100" iyz="0" izz="100" />
        </inertial>
        <visual>
            <origin xyz="0 0.8383363595142133 0" rpy="0 0 0"/>
            <geometry>
                <box size="1.224100101726435 1.6766727190284265 2.924671156546345" />
            </geometry>
            <material name="Green">
                <color rgba="0 180.0 0.0 1.0"/>
            </material>
        </visual>
        <collision>
            <origin xyz="0 0.8383363595142133 0" rpy="0 0 0"/>
            <geometry>
                <box size="1.224100101726435 1.6766727190284265 2.924671156546345" />
            </geometry>
        </collision>
    </link>
<link name="Torso2">
        <inertial>
            <origin xyz="0 1.470670641075713 0" rpy="0 0 0"/>
            <mass value="1" />
            <inertia ixx="100" ixy="0" ixz="0" iyy="100" iyz="0" izz="100" />
        </inertial>
        <visual>
            <origin xyz="0 1.470670641075713 0" rpy="0 0 0"/>
            <geometry>
                <box size="1.2008910080800483 2.941341282151426 2.8838277426088164" />
            </geometry>
            <material name="Blue">
                <color rgba="0 1.0 1.0 1.0"/>
            </material>
        </visual>
        <collision>
            <origin xyz="0 1.470670641075713 0" rpy="0 0 0"/>
            <geometry>
                <box size="1.2008910080800483 2.941341282151426 2.8838277426088164" />
            </geometry>
        </collision>
    </link>
<link name="Torso3">
        <inertial>
            <origin xyz="0 0.9718983962457826 0" rpy="0 0 0"/>
            <mass value="1" />
            <inertia ixx="100" ixy="0" ixz="0" iyy="100" iyz="0" izz="100" />
        </inertial>
        <visual>
            <origin xyz="0 0.9718983962457826 0" rpy="0 0 0"/>
            <geometry>
                <box size="2.5699573463099457 1.9437967924915651 1.4054651904760056" />
            </geometry>
            <material name="Blue">
                <color rgba="0 1.0 1.0 1.0"/>
            </material>
        </visual>
        <collision>
            <origin xyz="0 0.9718983962457826 0" rpy="0 0 0"/>
            <geometry>
                <box size="2.5699573463099457 1.9437967924915651 1.4054651904760056" />
            </geometry>
        </collision>
    </link>
<link name="Torso4">
        <inertial>
            <origin xyz="0 0.8920642539929 0" rpy="0 0 0"/>
            <mass value="1" />
            <inertia ixx="100" ixy="0" ixz="0" iyy="100" iyz="0" izz="100" />
        </inertial>
        <visual>
            <origin xyz="0 0.8920642539929 0" rpy="0 0 0"/>
            <geometry>
                <box size="1.9999749052512372 1.7841285079858 1.865389721329019" />
            </geometry>
            <material name="Green">
                <color rgba="0 180.0 0.0 1.0"/>
            </material>
        </visual>
        <collision>
            <origin xyz="0 0.8920642539929 0" rpy="0 0 0"/>
            <geometry>
                <box size="1.9999749052512372 1.7841285079858 1.865389721329019" />
            </geometry>
        </collision>
    </link>
<link name="Torso5">
        <inertial>
            <origin xyz="0 1.3184335958622473 0" rpy="0 0 0"/>
            <mass value="1" />
            <inertia ixx="100" ixy="0" ixz="0" iyy="100" iyz="0" izz="100" />
        </inertial>
        <visual>
            <origin xyz="0 1.3184335958622473 0" rpy="0 0 0"/>
            <geometry>
                <box size="1.1808011175007722 2.6368671917244946 1.179597812528219" />
            </geometry>
            <material name="Blue">
                <color rgba="0 1.0 1.0 1.0"/>
            </material>
        </visual>
        <collision>
            <origin xyz="0 1.3184335958622473 0" rpy="0 0 0"/>
            <geometry>
                <box size="1.1808011175007722 2.6368671917244946 1.179597812528219" />
            </geometry>
        </collision>
    </link>
<link name="Torso6">
        <inertial>
            <origin xyz="0 1.0876093338221107 0" rpy="0 0 0"/>
            <mass value="1" />
            <inertia ixx="100" ixy="0" ixz="0" iyy="100" iyz="0" izz="100" />
        </inertial>
        <visual>
            <origin xyz="0 1.0876093338221107 0" rpy="0 0 0"/>
            <geometry>
                <box size="2.1414305715627657 2.1752186676442213 1.1290098381433749" />
            </geometry>
            <material name="Blue">
                <color rgba="0 1.0 1.0 1.0"/>
            </material>
        </visual>
        <collision>
            <origin xyz="0 1.0876093338221107 0" rpy="0 0 0"/>
            <geometry>
                <box size="2.1414305715627657 2.1752186676442213 1.1290098381433749" />
            </geometry>
        </collision>
    </link>
    <joint name="Torso_Torso1" type="revolute">
       <parent link="Torso"/>
       <child  link="Torso1"/>
       <origin rpy="0 0 0" xyz="0 1.4015466686989018 0.6129705770482038" />
       <axis xyz="1 0 0"/>
       <limit effort="0.0" lower="-3.14159" upper="3.14159" velocity="0.0"/>
    </joint>
    <joint name="Torso1_Torso2" type="revolute">
       <parent link="Torso1"/>
       <child  link="Torso2"/>
       <origin rpy="0 0 0" xyz="0 0.8383363595142133 0" />
       <axis xyz="1 0 0"/>
       <limit effort="0.0" lower="-3.14159" upper="3.14159" velocity="0.0"/>
    </joint>
    <joint name="Torso2_Torso3" type="revolute">
       <parent link="Torso2"/>
       <child  link="Torso3"/>
       <origin rpy="0 0 0" xyz="0 0.8383363595142133 0" />
       <axis xyz="1 0 0"/>
       <limit effort="0.0" lower="-3.14159" upper="3.14159" velocity="0.0"/>
    </joint>
    <joint name="Torso3_Torso4" type="revolute">
       <parent link="Torso3"/>
       <child  link="Torso4"/>
       <origin rpy="0 0 0" xyz="0 0.8383363595142133 0" />
       <axis xyz="1 0 0"/>
       <limit effort="0.0" lower="-3.14159" upper="3.14159" velocity="0.0"/>
    </joint>
    <joint name="Torso4_Torso5" type="revolute">
       <parent link="Torso4"/>
       <child  link="Torso5"/>
       <origin rpy="0 0 0" xyz="0 0.8383363595142133 0" />
       <axis xyz="1 0 0"/>
       <limit effort="0.0" lower="-3.14159" upper="3.14159" velocity="0.0"/>
    </joint>
    <joint name="Torso5_Torso6" type="revolute">
       <parent link="Torso5"/>
       <child  link="Torso6"/>
       <origin rpy="0 0 0" xyz="0 0.8383363595142133 0" />
       <axis xyz="1 0 0"/>
       <limit effort="0.0" lower="-3.14159" upper="3.14159" velocity="0.0"/>
    </joint>
    <joint name="Torso6_Torso7" type="revolute">
       <parent link="Torso6"/>
       <child  link="Torso7"/>
       <origin rpy="0 0 0" xyz="0 0.8383363595142133 0" />
       <axis xyz="1 0 0"/>
       <limit effort="0.0" lower="-3.14159" upper="3.14159" velocity="0.0"/>
    </joint>
    <joint name="Torso7_Torso8" type="revolute">
       <parent link="Torso7"/>
       <child  link="Torso8"/>
       <origin rpy="0 0 0" xyz="0 0.8383363595142133 0" />
       <axis xyz="1 0 0"/>
       <limit effort="0.0" lower="-3.14159" upper="3.14159" velocity="0.0"/>
    </joint>
    <joint name="Torso8_Torso9" type="revolute">
       <parent link="Torso8"/>
       <child  link="Torso9"/>
       <origin rpy="0 0 0" xyz="0 0.8383363595142133 0" />
       <axis xyz="1 0 0"/>
       <limit effort="0.0" lower="-3.14159" upper="3.14159" velocity="0.0"/>
    </joint>
    <joint name="Torso9_Torso10" type="revolute">
       <parent link="Torso9"/>
       <child  link="Torso10"/>
       <origin rpy="0 0 0" xyz="0 0.8383363595142133 0" />
       <axis xyz="1 0 0"/>
       <limit effort="0.0" lower="-3.14159" upper="3.14159" velocity="0.0"/>
    </joint>
    <joint name="Torso10_Torso11" type="revolute">
       <parent link="Torso10"/>
       <child  link="Torso11"/>
       <origin rpy="0 0 0" xyz="0 0.8383363595142133 0" />
       <axis xyz="1 0 0"/>
       <limit effort="0.0" lower="-3.14159" upper="3.14159" velocity="0.0"/>
    </joint>
    <joint name="Torso11_Torso12" type="revolute">
       <parent link="Torso11"/>
       <child  link="Torso12"/>
       <origin rpy="0 0 0" xyz="0 0.8383363595142133 0" />
       <axis xyz="1 0 0"/>
       <limit effort="0.0" lower="-3.14159" upper="3.14159" velocity="0.0"/>
    </joint>
</robot>