<robot name = "robot">
<link name="torso">
        <inertial>
            <origin xyz="0 0 1" rpy="0 0 0"/>
            <mass value="1" />
            <inertia ixx="100" ixy="0" ixz="0" iyy="100" iyz="0" izz="100" />
        </inertial>
        <visual>
            <origin xyz="0 0 1" rpy="0 0 0"/>
            <geometry>
                <box size="2.4176227602488405 1.962145253664529 0.4186676516809571" />
            </geometry>
            <material name="blue">
                <color rgba="0 0 1 1"/>
            </material>
        </visual>
        <collision>
            <origin xyz="0 0 1" rpy="0 0 0"/>
            <geometry>
                <box size="2.4176227602488405 1.962145253664529 0.4186676516809571" />
            </geometry>
        </collision>
    </link>
    <joint name="torso_link1" type="revolute">
       <parent link="torso"/>
       <child  link="link1"/>
       <origin rpy="0 0 0" xyz="0.0 0.0 1" />
       <axis xyz="0 0 1"/>
       <limit effort="0.0" lower="-3.14159" upper="3.14159" velocity="0.0"/>
    </joint>
    <joint name="torso_link1" type="revolute">
       <parent link="torso"/>
       <child  link="link1"/>
       <origin rpy="0 0 0" xyz="0.0 0.0 1" />
       <axis xyz="1 0 0"/>
       <limit effort="0.0" lower="-3.14159" upper="3.14159" velocity="0.0"/>
    </joint>
<link name="Link0">
        <inertial>
            <origin xyz="0.0 0.0 1" rpy="0 0 0"/>
            <mass value="1" />
            <inertia ixx="100" ixy="0" ixz="0" iyy="100" iyz="0" izz="100" />
        </inertial>
        <visual>
            <origin xyz="0.0 0.0 1" rpy="0 0 0"/>
            <geometry>
                <box size="0.4186676516809571 0.3531932541447508 0.710968958621192" />
            </geometry>
            <material name="blue">
                <color rgba="0 0 1 1"/>
            </material>
        </visual>
        <collision>
            <origin xyz="0.0 0.0 1" rpy="0 0 0"/>
            <geometry>
                <box size="0.4186676516809571 0.3531932541447508 0.710968958621192" />
            </geometry>
        </collision>
    </link>
